<?xml version="1.0" encoding="UTF-8"?>
<robot name="carter v2">
   <link name="chassis_link">
      <visual>
         <origin rpy="0 0 0" xyz="0 0 0" />
         <geometry>
            <mesh filename="package://carter v2/meshes/chassis_link.obj" scale="0.01 0.01 0.01"/>
         </geometry>
      </visual>
      <collision>
         <origin rpy="0 0 0" xyz="-0.232 0.000000 0.27" />
         <geometry>
            <box size=".7 .336 .3"/>
         </geometry>
      </collision>
      <inertial>
         <origin rpy="0 0 0" xyz="-0.23.2 0.000000 0.27" />
         <mass value="45.88" />
         <inertia ixx="1.182744" ixy="0.017957" ixz="-0.077476" iyx="0.017957" iyy="0.538664" iyz="0.000018" izx="-0.077476" izy="0.000018" izz="1.240229"/>
      </inertial>
   </link>
   <link name="left_wheel_link">
      <visual>
         <origin rpy="0 0 -1.5707963267948966" xyz="0 0 0" />
         <geometry>
            <mesh filename="package://carter v2/meshes/wheel_link.obj" scale="0.01 0.01 0.01" />
         </geometry>
      </visual>
      <collision>
         <origin rpy="1.5707963267948966 -1.5707963267948966 0" xyz="0 0 0" />
         <geometry>
            <cylinder length = "0.055" radius = "0.1350"/>
         </geometry>
      </collision>
      <inertial>
         <origin rpy="0 0 0" xyz="0 0 0" />
         <mass value="4.195729" />
         <inertia ixx="0.063680" ixy="0.000000" ixz="0.000000" iyx="0.000000" iyy="0.121410" iyz="0.000000" izx="0.000000" izy="0.000000" izz="0.063680"/>
      </inertial>
   </link>
   <link name="right_wheel_link">
      <visual>
         <origin rpy="0 0 -1.5707963267948966" xyz="0 0 0" />
         <geometry>
            <mesh filename="package://carter v2/meshes/wheel_link.obj" scale="0.01 0.01 0.01" />
         </geometry>
         <material name="black"/>
      </visual>
      <collision>
         <origin rpy="-1.5707963267948966 -1.5707963267948966 0" xyz="0 0 0" />
         <geometry>
            <cylinder length = "0.055" radius = "0.1350"/>
         </geometry>
      </collision>
      <inertial>
         <origin rpy="0 0 0" xyz="0 0 0" />
         <mass value="4.195729" />
         <inertia ixx="0.063680" ixy="0.000000" ixz="0.000000" iyx="0.000000" iyy="0.121410" iyz="0.000000" izx="0.000000" izy="0.000000" izz="0.063680"/>
      </inertial>
   </link>
   <link name="rear_pivot_link">
      <visual>
         <origin rpy="1.5707963267948966 -1.5707963267948966 0" xyz="0 0 -0.0275" />
         <geometry>
            <mesh filename="package://carter v2/meshes/back_wheels_link.obj" scale = "0.01 0.01 0.01"/>
         </geometry>
         <material name="black"/>
      </visual>
      <collision>
         <origin rpy="0 0 0" xyz="0 0 -.035" />
         <geometry>
            <box size=".09 .33 .02"/>
         </geometry>
      </collision>
      <inertial>
         <origin rpy="0 0 0" xyz="0 0 -.035" />
         <mass value="0.579519"/>         
      </inertial>
   </link>
   <link name="swivel_left_link">
      <visual>
         <origin rpy="1.5707963267948966 0 3.14159" xyz="0 0 0" />
         <geometry>
            <mesh filename="package://carter v2/meshes/swivel_link.obj" scale = "0.01 0.01 0.01"/>
         </geometry>
      </visual>
      <collision>
         <origin rpy="1.5707963267948966 0 0" xyz="0 0 -0.06" />
         <geometry>
            <box size=".09 .08 .12"/>
         </geometry>
      </collision>
      <inertial>
         <origin rpy="1.5707963267948966 0 0" xyz="0.000000 0.000000 -0.06" />
         <mass value="1.25"/>
      </inertial>
   </link>
   <link name="swivel_right_link">
      <visual>
         <origin rpy="1.5707963267948966 0 3.14159" xyz="0 0 0" />
         <geometry>
            <mesh filename="package://carter v2/meshes/swivel_link.obj" scale = "0.01 0.01 0.01" />
         </geometry>
      </visual>
      <collision>
         <origin rpy="1.5707963267948966 0 0" xyz="0 0 -0.06" />
         <geometry>
            <box size=".09 .08 .12"/>
         </geometry>
      </collision>
      <inertial>
         <origin rpy="1.5707963267948966 0 0" xyz="0.000000 0.000000 -0.06" />
         <mass value="1.25"/>
      </inertial>
   </link>
   <link name="rear_wheel_left_link">
      <visual>
         <origin rpy="0 0 1.5707963267948966" xyz="0 0 0" />
         <geometry>
            <mesh filename="package://carter v2/meshes/caster_wheel_link.obj" scale = "0.01 0.01 0.01"/>
         </geometry>
      </visual>
      <collision>
         <origin rpy="1.5707963267948966 0 0" xyz="0 0 0" />
         <geometry>
            <cylinder length = "0.025" radius = "0.0755"/>
         </geometry>
      </collision>
      <inertial>
         <origin rpy="1.5707963267948966 0 0" xyz="0.000000 0.000000 0.000000" />
         <mass value="0.25"/>
         <inertia ixx="0.02888" ixy="0.000000" ixz="0.000000" iyx="0.000000" iyy="0.02888" iyz="0.000000" izx="0.000000" izy="0.000000" izz="0.02888"/>
      </inertial>
   </link>
   <link name="rear_wheel_right_link">
      <visual>
         <origin rpy="0 0 1.5707963267948966" xyz="0 0 0" />
         <geometry>
            <mesh filename="package://carter v2/meshes/caster_wheel_link.obj" scale = "0.01 0.01 0.01"/>
         </geometry>
      </visual>
      <collision>
         <origin rpy="1.5707963267948966 0 0" xyz="0 0 0" />
         <geometry>
            <cylinder length = "0.025" radius = "0.0755"/>
         </geometry>
      </collision>
      <inertial>
         <origin rpy="1.5707963267948966 0 0" xyz="0.000000 0.000000 0.000000" />
         <mass value="0.25"/>
         <inertia ixx="0.02888" ixy="0.000000" ixz="0.000000" iyx="0.000000" iyy="0.02888" iyz="0.000000" izx="0.000000" izy="0.000000" izz="0.02888"/>
      </inertial>
   </link>

   <joint name="left_wheel" type="continuous">      
      <origin rpy="0 0 0" xyz="0 -0.2066 0.140" />
      <axis xyz="0 1 0" />
      <parent link="chassis_link" />
      <child link="left_wheel_link" />
   </joint>
   <joint name="right_wheel" type="continuous">
      <origin rpy="0 0 0" xyz="0 0.2066 0.140" />
      <axis xyz="0 1 0" />
      <parent link="chassis_link" />
      <child link="right_wheel_link" />
   </joint>
   <joint name="rear_pivot" type="revolute">
      <origin rpy="0 0 0" xyz="-0.4735 0 0.2228921" />
      <axis xyz="1 0 0" />
      <limit upper="0.0872665" lower="-0.0872665" />
      <parent link="chassis_link" />
      <child link="rear_pivot_link" />
   </joint>
   <joint name="rear_swivel_right" type="continuous">
      <origin rpy="0 0 0" xyz="0 -0.13225 -0.04527" />
      <axis xyz="0 0 1" />
      <parent link="rear_pivot_link" />
      <child link="swivel_left_link" />
   </joint>
   <joint name="rear_swivel_left" type="continuous">
      <origin rpy="0 0 0" xyz="0 0.13225 -0.04527" />
      <axis xyz="0 0 1" />
      <parent link="rear_pivot_link" />
      <child link="swivel_right_link" />
   </joint>
   <joint name="rear_axle_left" type="continuous">
      <origin rpy="0 0 0" xyz="-.04 0 -.101315" />
      <axis xyz="0 1 0" />
      <parent link="swivel_left_link" />
      <child link="rear_wheel_left_link" />
   </joint>
   <joint name="rear_axle_right" type="continuous">
      <origin rpy="0 0 0" xyz="-.04 0 -.101315" />
      <axis xyz="0 1 0" />
      <parent link="swivel_right_link" />
      <child link="rear_wheel_right_link" />
   </joint>
</robot>